2019-09-25 22:48:52.947 ERROR deploy - __init__: [Errno 98] Address already in use
2019-09-25 22:48:52.948 ERROR deploy - __init__: None
2019-09-25 22:49:09.734 ERROR base - default_exception_handler: Future exception was never retrieved
future: <prompt_toolkit.eventloop.future.Future object at 0x7f0fe9058198>
Traceback (most recent call last):
  File "/usr/local/lib/python3.6/dist-packages/prompt_toolkit/eventloop/posix.py", line 154, in _run_task
    t()
  File "/usr/local/lib/python3.6/dist-packages/prompt_toolkit/eventloop/context.py", line 115, in new_func
    return func(*a, **kw)
  File "/usr/local/lib/python3.6/dist-packages/prompt_toolkit/application/application.py", line 566, in read_from_input
    f.set_exception(EOFError)
  File "/usr/local/lib/python3.6/dist-packages/prompt_toolkit/eventloop/future.py", line 106, in set_exception
    raise InvalidStateError('Future result has been set already.')
prompt_toolkit.eventloop.future.InvalidStateError: Future result has been set already.

During handling of the above exception, another exception occurred:

Traceback (most recent call last):
  File "/usr/local/lib/python3.6/dist-packages/prompt_toolkit/eventloop/coroutine.py", line 86, in step_next
    new_f = coroutine.send(None)
  File "/usr/local/lib/python3.6/dist-packages/prompt_toolkit/application/run_in_terminal.py", line 86, in _run_in_t
    app.renderer.erase()
  File "/usr/local/lib/python3.6/dist-packages/prompt_toolkit/renderer.py", line 619, in erase
    output.flush()
  File "/usr/local/lib/python3.6/dist-packages/prompt_toolkit/output/vt100.py", line 605, in flush
    self.stdout.flush()
OSError: [Errno 5] Input/output error
